<?xml version="1.0" ?>
<!-- =================================================================================== -->
<!-- |    This document was autogenerated by xacro from step2urdf.xacro                | -->
<!-- |    EDITING THIS FILE BY HAND IS NOT RECOMMENDED                                 | -->
<!-- =================================================================================== -->
<robot name="step2urdf">
  <material name="silver_default">
    <color rgba="0.700 0.700 0.700 1.000"/>
  </material>
  <material name="opaque202209238">
    <color rgba="0.792156862745098 0.8196078431372549 0.9333333333333333 1.0"/>
  </material>
  <material name="black">
    <color rgba="0.4 0.4 0.4 1.0"/>
  </material>




  <transmission name="Wheel_L_tran">
    <type>transmission_interface/SimpleTransmission</type>
    <joint name="Wheel_L">
      <hardwareInterface>hardware_interface/VelocityJointInterface</hardwareInterface>
    </joint>
    <actuator name="Wheel_L_actr">
      <hardwareInterface>hardware_interface/VelocityJointInterface</hardwareInterface>
      <mechanicalReduction>1</mechanicalReduction>
    </actuator>
  </transmission>



  <transmission name="Wheel_R_tran">
    <type>transmission_interface/SimpleTransmission</type>
    <joint name="Wheel_R">
      <hardwareInterface>hardware_interface/VelocityJointInterface</hardwareInterface>
    </joint>
    <actuator name="Wheel_R_actr">
      <hardwareInterface>hardware_interface/VelocityJointInterface</hardwareInterface>
      <mechanicalReduction>1</mechanicalReduction>
    </actuator>
  </transmission>



  <gazebo>
    <plugin filename="libgazebo_ros_control.so" name="control"/>
  </gazebo>

  <gazebo>
    <plugin name="gazebo_ros_control" filename="libgazebo_ros_control.so">
      <robotNamespace>/dtw_robot</robotNamespace>
      <robotSimType>gazebo_ros_control/DefaultRobotHWSim</robotSimType>
      <legacyModeNS>true</legacyModeNS>
    </plugin>
  </gazebo>

  <gazebo reference="body">
    <material>Gazebo/Silver</material>
    <mu1>0.2</mu1>
    <mu2>0.2</mu2>
    <selfCollide>true</selfCollide>
    <gravity>true</gravity>
  </gazebo>
  <gazebo reference="Link_1_v1_1">
    <material>Gazebo/Silver</material>
    <mu1>0.2</mu1>
    <mu2>0.2</mu2>
    <selfCollide>true</selfCollide>
  </gazebo>
  <gazebo reference="Link_2_v1_1">
    <material>Gazebo/Silver</material>
    <mu1>0.2</mu1>
    <mu2>0.2</mu2>
    <selfCollide>true</selfCollide>
  </gazebo>
	<gazebo reference="caster">
		<mu1>0.0</mu1>
		<mu2>0.0</mu2>
		<material>Gazebo/Green</material>
	</gazebo>
	<gazebo reference="lidar_base">
		<mu1>0.0</mu1>
		<mu2>0.0</mu2>
		<material>Gazebo/Yellow</material>
	</gazebo>

	<gazebo reference="lidar_link">
		<mu1>0.0</mu1>
		<mu2>0.0</mu2>
		<material>Gazebo/Purple</material>
	</gazebo>



<!--機能的な部分をロードするための追加要素-->
  <gazebo>
    <!--差動駆動プラグインを指定-->
    <plugin name="differential_drive_controller" filename="libgazebo_ros_diff_drive.so">
      <!--left_wheel_jointとright_wheel_jointをそれぞれ左関節右関節に指定-->
      <leftJoint>Link_1_v1_1</leftJoint>
      <rightJoint>Link_2_v1_1</rightJoint>
      <!--台座であるbase_linkをrobotBaseFrameに指定-->
      <robotBaseFrame>body</robotBaseFrame>
      <!--トレッドを0.25m，車輪直径0.07mとする-->
      <wheelSeparation>0.400</wheelSeparation>
      <wheelDiameter>0.286</wheelDiameter>
      <!--車輪の状態を配信する設定にする-->
      <publishWheelJointState>true</publishWheelJointState>
    </plugin>

    <!--関節状態配信プラグインを指定-->

  </gazebo>

  <!--レーザセンサを定義する-->
  <gazebo reference="lidar_link">
    <sensor type="ray" name="rpLiDAR">
    <!--sensor type="gpu_ray" name="hokuyo"-->
      <pose>0 0 0 0 0 0 </pose>
      <visualize>true</visualize>
      <update_rate>40</update_rate>
      <ray>
        <scan>
          <horizontal>
            <samples>720</samples>
            <resolution>1</resolution>
            <min_angle>-3.14</min_angle>
            <max_angle>3.14</max_angle>
          </horizontal>
        </scan>
        <range>
          <min>0.10</min>
          <max>6.0</max>
          <resolution>0.01</resolution>
        </range>
        <noise>
          <type>gaussian</type>
          <!-- Noise parameters based on published spec for Hokuyo laser
               achieving "+-30mm" accuracy at range < 10m.  A mean of 0.0m and
               stddev of 0.01m will put 99.7% of samples within 0.03m of the true
               reading. -->
          <mean>0.0</mean>
          <stddev>0.01</stddev>
        </noise>
      </ray>
      <!--レーザセンサのためのプラグインを指定-->
      <plugin name="laser" filename="libgazebo_ros_laser.so">
      <!--plugin name="gpu_laser" filename="libgazebo_ros_gpu_laser.so"-->
        <topicName>/scan</topicName>
        <frameName>lidar_link</frameName>
      </plugin>
    </sensor>
  </gazebo>




  <link name ="base_link">
  </link>

  <link name="body">
    <inertial>
      <origin rpy="0 0 0" xyz="-0.0797893829175013 0.021321971265732098 0.19796992913112318"/>
      <mass value="44.96014807733396"/>
      <inertia ixx="0.70697" ixy="0.086557" ixz="0.093364" iyy="0.773527" iyz="0.015459" izz="1.085054"/>
    </inertial>
    <visual>
      <origin rpy="0 0 0" xyz="0 0 0"/>
      <geometry>
        <mesh filename="package://step2urdf_description/meshes/base_link.stl" scale="0.001 0.001 0.001"/>
      </geometry>
      <material name="opaque202209238"/>
    </visual>
    <collision>
      <origin rpy="0 0 0" xyz="0 0 0"/>
      <geometry>
        <mesh filename="package://step2urdf_description/meshes/base_link.stl" scale="0.001 0.001 0.001"/>
      </geometry>
    </collision>
  </link>



  <link name="Link_1_v1_1">
    <inertial>
      <origin rpy="0 0 0" xyz="5.904390531910397e-06 0.031875191382541246 2.7755575615628914e-17"/>
      <mass value="34.12618496286369"/>
      <inertia ixx="0.201769" ixy="-0.0" ixz="-0.0" iyy="0.36795" iyz="0.0" izz="0.201766"/>
    </inertial>
    <visual>
      <origin rpy="0 0 0" xyz="-0.0 0.2287 -0.143"/>
      <geometry>
        <mesh filename="package://step2urdf_description/meshes/Link_1_v1_1.stl" scale="0.001 0.001 0.001"/>
      </geometry>
      <material name="black"/>
    </visual>
    <collision>
      <origin rpy="0 0 0" xyz="-0.0 0.2287 -0.143"/>
      <geometry>
        <mesh filename="package://step2urdf_description/meshes/Link_1_v1_1.stl" scale="0.001 0.001 0.001"/>
      </geometry>
    </collision>
  </link>



  <link name="Link_2_v1_1">
    <inertial>
      <origin rpy="0 0 0" xyz="2.3801841665793685e-06 -0.03187519138254108 5.403383278868024e-06"/>
      <mass value="34.12618496286369"/>
      <inertia ixx="0.201766" ixy="0.0" ixz="1e-06" iyy="0.36795" iyz="0.0" izz="0.201768"/>
    </inertial>
    <visual>
      <origin rpy="0 0 0" xyz="0.0 -0.2287 -0.143"/>
      <geometry>
        <mesh filename="package://step2urdf_description/meshes/Link_2_v1_1.stl" scale="0.001 0.001 0.001"/>
      </geometry>
      <material name="black"/>
    </visual>
    <collision>
      <origin rpy="0 0 0" xyz="0.0 -0.2287 -0.143"/>
      <geometry>
        <mesh filename="package://step2urdf_description/meshes/Link_2_v1_1.stl" scale="0.001 0.001 0.001"/>
      </geometry>
    </collision>
  </link>

  <!-- キャスターの作成 -->
  <link name="caster">
    <visual>
      <geometry>
        <sphere radius="0.093"/>
      </geometry>
      <origin xyz="0 0 0" rpy="0 0 0"/>
      <material name="black">
        <color rgba="0.0 1.0 0.0 1.0"/>
      </material>
    </visual>
    <collision>
      <origin rpy="0 0 0" xyz="0 0 0.0"/>
      <geometry>
        <sphere radius="0.093"/>
      </geometry>
    </collision>
    <!--慣性-->
    <inertial>
        <mass value="0.5"/>
        <inertia ixx="3.000e-4" iyy="3.000e-4" izz="3.000e-4" ixy="0" ixz="0" iyz="0"/>
    </inertial>
  </link>

  <!-- Lidar台の作成 -->
  <link name="lidar_base">
    <visual>
      <geometry>
        <box size="0.03 0.03 0.27"/>
      </geometry>
      <origin xyz="0 0 0" rpy="0 0 0"/>
      <material name="opaque202209238">
        <color rgba="1.0 1.0 0.0 1.0"/>
      </material>
    </visual>
    <collision>
      <origin rpy="0 0 0" xyz="0 0 0.0"/>
      <geometry>
        <box size="0.1 0.1 0.1"/>
      </geometry>
    </collision>
    <!--慣性-->
    <inertial>
        <mass value="0.15"/>
        <inertia ixx="0.25" iyy="0.25" izz="0.25" ixy="0" ixz="0" iyz="0"/>
    </inertial>
  </link>

  <!-- Lidarの作成 -->
  <link name="lidar_link">
    <visual>
      <geometry>
        <cylinder radius="0.05" length="0.05"/>
      </geometry>
      <origin xyz="0 0 0" rpy="0 0 0"/>
      <material name="purple">
        <color rgba="1.0 0.0 1.0 1.0"/>
      </material>
    </visual>
    <collision>
      <origin rpy="0 0 0" xyz="0 0 0.0"/>
      <geometry>
        <cylinder radius="0.05" length="0.05"/>
      </geometry>
    </collision>
    <!--慣性-->
    <inertial>
        <mass value="0.15"/>
        <inertia ixx="0.125" iyy="0.125" izz="0.188" ixy="0" ixz="0" iyz="0"/>
    </inertial>
  </link>


  <joint name="base_joint" type="fixed">
    <origin rpy="0 0 0" xyz="0 0 0"/>
    <parent link="base_link"/>
    <child link="body"/>
  </joint>


  <joint name="Wheel_L_joint" type="continuous">
    <origin rpy="0 0 0" xyz="0.0 -0.2287 0.143"/>
    <parent link="body"/>
    <child link="Link_1_v1_1"/>
    <axis xyz="0.0 -1.0 0.0"/>
    <limit velocity="12.0" effort="0.4" />
    <dynamics damping="0.1"/>
  </joint>



  <joint name="Wheel_R_joint" type="continuous">
    <origin rpy="0 0 0" xyz="0.0 0.2287 0.143"/>
    <parent link="body"/>
    <child link="Link_2_v1_1"/>
    <axis xyz="0.0 -1.0 -0.0"/>
    <limit velocity="12.0" effort="0.4" />
    <dynamics damping="0.1"/>
  </joint>

	<joint name="caster_joint" type="fixed">
    <origin xyz="-0.332 0 0.096" rpy="0 0 0"/>
    <parent link="body"/>
    <child link="caster"/>
	</joint>

	<joint name="lidar_base_joint" type="fixed">
    <origin xyz="-0.362 -0.235 0.393" rpy="0 0 0"/>
    <parent link="body"/>
    <child link="lidar_base"/>
	</joint>

	<joint name="lidar_joint" type="fixed">
    <origin xyz="0.0 0.0 0.155" rpy="0 0 0"/>
    <parent link="lidar_base"/>
    <child link="lidar_link"/>
	</joint>



</robot>
